#VRML_SIM R2023b utf8

EXTERNPROTO "https://raw.githubusercontent.com/cyberbotics/webots/R2023b/projects/objects/backgrounds/protos/TexturedBackground.proto"
EXTERNPROTO "https://raw.githubusercontent.com/cyberbotics/webots/R2023b/projects/objects/backgrounds/protos/TexturedBackgroundLight.proto"
EXTERNPROTO "https://raw.githubusercontent.com/cyberbotics/webots/R2023b/projects/objects/floors/protos/RectangleArena.proto"

WorldInfo {
}
Viewpoint {
  orientation -0.5070142837209946 0.6138660089973217 0.6050661444012438 2.204000520797049
  position 4.717273270393988 2.7119059586545364 10.959553092942713
  follow "robot"
}
TexturedBackground {
}
TexturedBackgroundLight {
}
RectangleArena {
  translation 2.5 2.5 0
  floorSize 5 5
}
DEF robot Robot {
  translation 0.15540639587804952 2.37480347599742 -0.00020645499006345658
  rotation -0.013905069116249098 0.014462023305374853 0.9997987292124285 -1.6102454551368615
  children [
    InertialUnit {
    }
    GPS {
    }
    DEF body Pose {
      translation 0 0 0.0415
      children [
        Shape {
          appearance PBRAppearance {
            baseColor 0 0 1
            roughness 1
            metalness 0
          }
          geometry Cylinder {
            height 0.08
            radius 0.045
          }
        }
      ]
    }
    HingeJoint {
      jointParameters HingeJointParameters {
        position 311.02563291515656
        anchor 0.045 0 0.025
      }
      device [
        RotationalMotor {
          name "motor_1"
        }
        PositionSensor {
          name "ps_1"
        }
      ]
      endPoint Solid {
        translation 0.045 0 0.025
        rotation -0.7073854699092118 0.002813242077729766 -0.7068223840756146 3.1359617020080295
        children [
          DEF wheel Shape {
            appearance PBRAppearance {
              baseColor 1 0 0
              roughness 1
              metalness 0
            }
            geometry Cylinder {
              height 0.01
              radius 0.025
            }
          }
        ]
        boundingObject USE wheel
        physics DEF wheel_physics Physics {
        }
        linearVelocity 2.6027426989845977e-07 5.577943497368791e-07 -5.369592903672625e-08
        angularVelocity -1.470154724302395e-06 8.5359317107508e-06 -3.706902864501272e-06
      }
    }
    HingeJoint {
      jointParameters HingeJointParameters {
        position 339.67243989878045
        anchor -0.045 0 0.025
      }
      device [
        RotationalMotor {
          name "motor_2"
        }
        PositionSensor {
          name "ps_2"
        }
      ]
      endPoint Solid {
        translation -0.045 0 0.025
        rotation 0.1859230488351239 0.9648420854595331 0.18577505224854945 1.605783692677676
        children [
          USE wheel
        ]
        name "solid(1)"
        boundingObject USE wheel
        physics USE wheel_physics
        linearVelocity 1.5756077702376274e-07 -5.383542581017868e-07 -8.725498688025855e-08
        angularVelocity -1.5549839969354677e-06 8.536275882588437e-06 -3.568570445208127e-06
      }
    }
    Solid {
      translation 0.015 -0.045 0.07
      children [
        DEF eye Shape {
          appearance PBRAppearance {
            baseColor 1 0 0
            roughness 1
            metalness 0
          }
          geometry Box {
            size 0.005 0.005 0.005
          }
        }
      ]
      name "solid(2)"
    }
    Solid {
      translation -0.015 -0.045 0.07
      children [
        USE eye
      ]
      name "solid(3)"
    }
  ]
  boundingObject USE body
  physics Physics {
  }
  controller "robot_controller"
  linearVelocity 3.661364828775445e-07 6.736415524356284e-08 -6.80682465990233e-08
  angularVelocity -4.610270177593007e-08 8.478688103690515e-06 -1.0714192165454772e-06
}
DEF wall_x Solid {
  translation 0.625 0.175 0
  children [
    Shape {
      appearance PBRAppearance {
        baseColor 0 0 0
        roughness 1
        metalness 0
      }
      geometry Box {
        size 0.125 0.375 0.25
      }
    }
  ]
  name "wall"
}
DEF wall_x Solid {
  translation 4.355 4.805 0
  children [
    Shape {
      appearance PBRAppearance {
        baseColor 0 0 0
        roughness 1
        metalness 0
      }
      geometry Box {
        size 0.125 0.375 0.25
      }
    }
  ]
  name "wall(20)"
}
DEF wall_x Solid {
  translation 0.385 1.695 0
  rotation 0 1 0 0
  children [
    Shape {
      appearance PBRAppearance {
        baseColor 0 0 0
        roughness 1
        metalness 0
      }
      geometry Box {
        size 0.125 0.775 0.25
      }
    }
  ]
  name "wall(4)"
}
DEF wall_x Solid {
  translation 1.835 1.695 0
  rotation 0 1 0 0
  children [
    Shape {
      appearance PBRAppearance {
        baseColor 0 0 0
        roughness 1
        metalness 0
      }
      geometry Box {
        size 0.125 0.775 0.25
      }
    }
  ]
  name "wall(2)"
}
DEF wall_x Solid {
  translation 1.835 4.205 0
  rotation 0 1 0 0
  children [
    Shape {
      appearance PBRAppearance {
        baseColor 0 0 0
        roughness 1
        metalness 0
      }
      geometry Box {
        size 0.125 0.775 0.25
      }
    }
  ]
  name "wall(17)"
}
DEF wall_x Solid {
  translation 2.635 1.095 0
  rotation 0 1 0 0
  children [
    Shape {
      appearance PBRAppearance {
        baseColor 0 0 0
        roughness 1
        metalness 0
      }
      geometry Box {
        size 0.125 1 0.25
      }
    }
  ]
  name "wall(6)"
}
DEF wall_x Solid {
  translation 3.135 3.355 0
  rotation 0 1 0 0
  children [
    Shape {
      appearance PBRAppearance {
        baseColor 0 0 0
        roughness 1
        metalness 0
      }
      geometry Box {
        size 0.125 1.5 0.25
      }
    }
  ]
  name "wall(14)"
}
DEF wall_x Solid {
  translation 4.135 0.845 0
  rotation 0 1 0 0
  children [
    Shape {
      appearance PBRAppearance {
        baseColor 0 0 0
        roughness 1
        metalness 0
      }
      geometry Box {
        size 0.125 1 0.25
      }
    }
  ]
  name "wall(8)"
}
DEF wall_x Solid {
  translation 0.625 3.655 0
  rotation 0 1 0 0
  children [
    Shape {
      appearance PBRAppearance {
        baseColor 0 0 0
        roughness 1
        metalness 0
      }
      geometry Box {
        size 0.125 1 0.25
      }
    }
  ]
  name "wall(18)"
}
DEF wall_y Solid {
  translation 0.8525 0.375 0
  rotation 0 0 1 1.5708
  children [
    Shape {
      appearance PBRAppearance {
        baseColor 0 0 0
        roughness 1
        metalness 0
      }
      geometry Box {
        size 0.125 0.575 0.25
      }
    }
  ]
  name "wall(21)"
}
DEF wall_y Solid {
  translation 4.13248 4.625 0
  rotation 0 0 1 1.5708
  children [
    Shape {
      appearance PBRAppearance {
        baseColor 0 0 0
        roughness 1
        metalness 0
      }
      geometry Box {
        size 0.125 0.575 0.25
      }
    }
  ]
  name "wall(19)"
}
DEF wall_y Solid {
  translation 2.4025 1.625 0
  rotation 0 0 1 1.5708
  children [
    Shape {
      appearance PBRAppearance {
        baseColor 0 0 0
        roughness 1
        metalness 0
      }
      geometry Box {
        size 0.125 1 0.25
      }
    }
  ]
  name "wall(5)"
}
DEF wall_y Solid {
  translation 3.8625 1.375 0
  rotation 0 0 1 1.5708
  children [
    Shape {
      appearance PBRAppearance {
        baseColor 0 0 0
        roughness 1
        metalness 0
      }
      geometry Box {
        size 0.125 0.6625 0.25
      }
    }
  ]
  name "wall(9)"
}
DEF wall_y Solid {
  translation 3.7325 0.375 0
  rotation 0 0 1 1.5708
  children [
    Shape {
      appearance PBRAppearance {
        baseColor 0 0 0
        roughness 1
        metalness 0
      }
      geometry Box {
        size 0.125 0.925 0.25
      }
    }
  ]
  name "wall(10)"
}
DEF wall_y Solid {
  translation 4.6325 2.125 0
  rotation 0 0 1 1.5708
  children [
    Shape {
      appearance PBRAppearance {
        baseColor 0 0 0
        roughness 1
        metalness 0
      }
      geometry Box {
        size 0.125 0.775 0.25
      }
    }
  ]
  name "wall(13)"
}
DEF wall_y Solid {
  translation 4.5725 0.625 0
  rotation 0 0 1 1.5708
  children [
    Shape {
      appearance PBRAppearance {
        baseColor 0 0 0
        roughness 1
        metalness 0
      }
      geometry Box {
        size 0.125 1 0.25
      }
    }
  ]
  name "wall(7)"
}
DEF wall_y Solid {
  translation 1.1025 1.375 0
  rotation 0 0 1 1.5708
  children [
    Shape {
      appearance PBRAppearance {
        baseColor 0 0 0
        roughness 1
        metalness 0
      }
      geometry Box {
        size 0.125 1.5 0.25
      }
    }
  ]
  name "wall(1)"
}
DEF wall_y Solid {
  translation 1.1025 3.125 0
  rotation 0 0 1 1.5708
  children [
    Shape {
      appearance PBRAppearance {
        baseColor 0 0 0
        roughness 1
        metalness 0
      }
      geometry Box {
        size 0.125 1.5 0.25
      }
    }
  ]
  name "wall(11)"
}
DEF wall_y Solid {
  translation 2.3425 3.875 0
  rotation 0 0 1 1.5708
  children [
    Shape {
      appearance PBRAppearance {
        baseColor 0 0 0
        roughness 1
        metalness 0
      }
      geometry Box {
        size 0.125 1.5 0.25
      }
    }
  ]
  name "wall(16)"
}
DEF wall_y Solid {
  translation 3.8625 3.625 0
  rotation 0 0 1 1.5708
  children [
    Shape {
      appearance PBRAppearance {
        baseColor 0 0 0
        roughness 1
        metalness 0
      }
      geometry Box {
        size 0.125 1.5 0.25
      }
    }
  ]
  name "wall(15)"
}
DEF wall_y Solid {
  translation 3.1025 2.625 0
  rotation 0 0 1 1.5708
  children [
    Shape {
      appearance PBRAppearance {
        baseColor 0 0 0
        roughness 1
        metalness 0
      }
      geometry Box {
        size 0.125 1.5 0.25
      }
    }
  ]
  name "wall(12)"
}
DEF wall_y Solid {
  translation 0.4625 2.125 0
  rotation 0 0 1 1.5708
  children [
    Shape {
      appearance PBRAppearance {
        baseColor 0 0 0
        roughness 1
        metalness 0
      }
      geometry Box {
        size 0.125 0.925 0.25
      }
    }
  ]
  name "wall(3)"
}
